Workbook
Name UPDATE: 'Data Sheet'!$E$1

Sheet Financials>

Sheet Historical FS
B2: ='Data Sheet'!B1 -> TATA MOTORS LTD
B3: ="Historcial Financial Statements - " & B2 -> Historcial Financial Statements - TATA MOTORS LTD
B4: Years | C4: ='Data Sheet'!B16 -> 41729 | D4: ='Data Sheet'!C16 -> 42094 | E4: ='Data Sheet'!D16 -> 42460 | F4: ='Data Sheet'!E16 -> 42825 | G4: ='Data Sheet'!F16 -> 43190 | H4: ='Data Sheet'!G16 -> 43555 | I4: ='Data Sheet'!H16 -> 43921 | J4: ='Data Sheet'!I16 -> 44286 | ... L4: ='Data Sheet'!K16 -> 45016 | M4: LTM
A6: # | B6: Income Statement
B7: Sales | C7: =IFERROR('Data Sheet'!B17,0) -> 232833.66 | D7: =IFERROR('Data Sheet'!C17,0) -> 263158.98 | E7: =IFERROR('Data Sheet'!D17,0) -> 273045.6 | F7: =IFERROR('Data Sheet'!E17,0) -> 269692.51 | G7: =IFERROR('Data Sheet'!F17,0) -> 291550.48 | H7: =IFERROR('Data Sheet'!G17,0) -> 301938.4 | I7: =IFERROR('Data Sheet'!H17,0) -> 261067.97 | J7: =IFERROR('Data Sheet'!I17,0) -> 249794.75 | ... L7: =IFERROR('Data Sheet'!K17,0) -> 345966.97 | M7: =IFERROR(SUM('Data Sheet'!H42:K42),0) -> 401785.26
B8: Sales Growth | C8: - | D8: =(D7/C7)-1 -> 0.13024457 | E8: =(E7/D7)-1 -> 0.037569001 | F8: =(F7/E7)-1 -> -0.01228033 | G8: =(G7/F7)-1 -> 0.081047746 | H8: =(H7/G7)-1 -> 0.035629919 | I8: =(I7/H7)-1 -> -0.13536016 | J8: =(J7/I7)-1 -> -0.043181168 | K8: =(K7/J7)-1 -> 0.11472967 | ... M8: =(M7/L7)-1 -> 0.16133994
B10: COGS | C10: =IFERROR(SUM('Data Sheet'!B18,'Data Sheet'!B20:B22) - 1*'Data Sheet'!B19,0) -> 180131.06 | D10: =IFERROR(SUM('Data Sheet'!C18,'Data Sheet'!C20:C22) - 1*'Data Sheet'!C19,0) -> 202856.88 | E10: =IFERROR(SUM('Data Sheet'!D18,'Data Sheet'!D20:D22) - 1*'Data Sheet'!D19,0) -> 205509.07 | F10: =IFERROR(SUM('Data Sheet'!E18,'Data Sheet'!E20:E22) - 1*'Data Sheet'!E19,0) -> 205454.24 | G10: =IFERROR(SUM('Data Sheet'!F18,'Data Sheet'!F20:F22) - 1*'Data Sheet'!F19,0) -> 228429.83 | H10: =IFERROR(SUM('Data Sheet'!G18,'Data Sheet'!G20:G22) - 1*'Data Sheet'!G19,0) -> 242845.53 | I10: =IFERROR(SUM('Data Sheet'!H18,'Data Sheet'!H20:H22) - 1*'Data Sheet'!H19,0) -> 210376.07 | J10: =IFERROR(SUM('Data Sheet'!I18,'Data Sheet'!I20:I22) - 1*'Data Sheet'!I19,0) -> 195326.04 | ... L10: =IFERROR(SUM('Data Sheet'!K18,'Data Sheet'!K20:K22) - 1*'Data Sheet'!K19,0) -> 274403.64 | M10: =IFERROR(SUM('Data Sheet'!H43:K43),0) -> 350865.96
B11: COGS % Sales | C11: =C10/C7 -> 0.77364699 | D11: =D10/D7 -> 0.77085297 | E11: =E10/E7 -> 0.75265476 | F11: =F10/F7 -> 0.76180922 | G11: =G10/G7 -> 0.7835001 | H11: =H10/H7 -> 0.80428833 | I11: =I10/I7 -> 0.80582873 | J11: =J10/J7 -> 0.78194614 | ... M11: =M10/M7 -> 0.87326738
B13: Gross Profit | C13: =C7-C10 -> 52702.6 | D13: =D7-D10 -> 60302.1 | E13: =E7-E10 -> 67536.53 | F13: =F7-F10 -> 64238.27 | G13: =G7-G10 -> 63120.65 | H13: =H7-H10 -> 59092.87 | I13: =I7-I10 -> 50691.9 | J13: =J7-J10 -> 54468.71 | ... M13: =M7-M10 -> 50919.3
B14: Gross Margins | C14: =C13/C7 -> 0.22635301 | D14: =D13/D7 -> 0.22914703 | E14: =E13/E7 -> 0.24734524 | F14: =F13/F7 -> 0.23819078 | G14: =G13/G7 -> 0.2164999 | H14: =H13/H7 -> 0.19571167 | I14: =I13/I7 -> 0.19417127 | J14: =J13/J7 -> 0.21805386 | ... M14: =M13/M7 -> 0.12673262
B16: Selling and General Expense | C16: =IFERROR(SUM('Data Sheet'!B23:B24),0) -> 17849.24 | D16: =IFERROR(SUM('Data Sheet'!C23:C24),0) -> 21063.45 | E16: =IFERROR(SUM('Data Sheet'!D23:D24),0) -> 29141.28 | F16: =IFERROR(SUM('Data Sheet'!E23:E24),0) -> 34649.58 | G16: =IFERROR(SUM('Data Sheet'!F23:F24),0) -> 31662.97 | H16: =IFERROR(SUM('Data Sheet'!G23:G24),0) -> 34428.54 | I16: =IFERROR(SUM('Data Sheet'!H23:H24),0) -> 32704.83 | J16: =IFERROR(SUM('Data Sheet'!I23:I24),0) -> 22181.28 | ... M16: =IFERROR(SUM('Data Sheet'!L23:L24),0) -> 0
B17: S&G Expenses % Sales | C17: =C16/C7 -> 0.076660909 | D17: =D16/D7 -> 0.08004078 | E17: =E16/E7 -> 0.10672679 | F17: =F16/F7 -> 0.1284781 | G17: =G16/G7 -> 0.10860202 | H17: =H16/H7 -> 0.11402505 | I17: =I16/I7 -> 0.12527324 | J17: =J16/J7 -> 0.088798023 | ... M17: =M16/M7 -> 0
B19: EBITDA | C19: =C13-C16 -> 34853.36 | D19: =D13-D16 -> 39238.65 | E19: =E13-E16 -> 38395.25 | F19: =F13-F16 -> 29588.69 | G19: =G13-G16 -> 31457.68 | H19: =H13-H16 -> 24664.33 | I19: =I13-I16 -> 17987.07 | J19: =J13-J16 -> 32287.43 | ... M19: =M13-M16 -> 50919.3
B20: EBITDA Margins | C20: =C19/C7 -> 0.1496921 | D20: =D19/D7 -> 0.14910626 | E20: =E19/E7 -> 0.14061845 | F20: =F19/F7 -> 0.10971269 | G20: =G19/G7 -> 0.10789788 | H20: =H19/H7 -> 0.081686629 | I20: =I19/I7 -> 0.068898034 | J20: =J19/J7 -> 0.12925584 | ... M20: =M19/M7 -> 0.12673262
B22: Interest | C22: =IFERROR('Data Sheet'!B27,0) -> 4749.44 | D22: =IFERROR('Data Sheet'!C27,0) -> 4861.49 | E22: =IFERROR('Data Sheet'!D27,0) -> 4889.08 | F22: =IFERROR('Data Sheet'!E27,0) -> 4238.01 | G22: =IFERROR('Data Sheet'!F27,0) -> 4681.79 | H22: =IFERROR('Data Sheet'!G27,0) -> 5758.6 | I22: =IFERROR('Data Sheet'!H27,0) -> 7243.33 | J22: =IFERROR('Data Sheet'!I27,0) -> 8097.17 | ... L22: =IFERROR('Data Sheet'!K27,0) -> 10225.48 | M22: =IFERROR(SUM('Data Sheet'!H46:K46),0) -> 10584.58
B23: Interest % Sales | C23: =C22/C7 -> 0.020398425 | D23: =D22/D7 -> 0.018473586 | E23: =E22/E7 -> 0.017905727 | F23: =F22/F7 -> 0.01571423 | G23: =G22/G7 -> 0.016058248 | H23: =H22/H7 -> 0.019072102 | I23: =I22/I7 -> 0.027744997 | J23: =J22/J7 -> 0.032415293 | ... M23: =M22/M7 -> 0.026343873
B25: Depreciation | C25: =IFERROR('Data Sheet'!B26,0) -> 11078.16 | D25: =IFERROR('Data Sheet'!C26,0) -> 13388.63 | E25: =IFERROR('Data Sheet'!D26,0) -> 16710.78 | F25: =IFERROR('Data Sheet'!E26,0) -> 17904.99 | G25: =IFERROR('Data Sheet'!F26,0) -> 21553.59 | H25: =IFERROR('Data Sheet'!G26,0) -> 23590.63 | I25: =IFERROR('Data Sheet'!H26,0) -> 21425.43 | J25: =IFERROR('Data Sheet'!I26,0) -> 23546.71 | ... M25: =IFERROR('Data Sheet'!L26,0) -> 0
B26: Depreciation % sales | C26: =C25/C7 -> 0.047579718 | D26: =D25/D7 -> 0.050876584 | E26: =E25/E7 -> 0.061201426 | F26: =F25/F7 -> 0.066390387 | G26: =G25/G7 -> 0.073927472 | H26: =H25/H7 -> 0.078130605 | I26: =I25/I7 -> 0.082068398 | J26: =J25/J7 -> 0.094264231 | ... M26: =M25/M7 -> 0
B28: Earnings Before Tax | C28: =IFERROR(C19-C22-C25,0) -> 19025.76 | D28: =IFERROR(D19-D22-D25,0) -> 20988.53 | E28: =IFERROR(E19-E22-E25,0) -> 16795.39 | F28: =IFERROR(F19-F22-F25,0) -> 7445.69 | G28: =IFERROR(G19-G22-G25,0) -> 5222.3 | H28: =IFERROR(H19-H22-H25,0) -> -4684.9 | I28: =IFERROR(I19-I22-I25,0) -> -10681.69 | J28: =IFERROR(J19-J22-J25,0) -> 643.55 | ... M28: =IFERROR(M19-M22-M25,0) -> 40334.72
B29: EBT % Sales | C29: =C28/C7 -> 0.081713958 | D29: =D28/D7 -> 0.079756085 | E29: =E28/E7 -> 0.061511301 | F29: =F28/F7 -> 0.027608071 | G29: =G28/G7 -> 0.017912164 | H29: =H28/H7 -> -0.015516079 | I29: =I28/I7 -> -0.04091536 | J29: =J28/J7 -> 0.0025763152 | ... M29: =M28/M7 -> 0.10038875
B31: Tax | C31: =IFERROR('Data Sheet'!B29,0) -> 4764.79 | D31: =IFERROR('Data Sheet'!C29,0) -> 7642.91 | E31: =IFERROR('Data Sheet'!D29,0) -> 3025.05 | F31: =IFERROR('Data Sheet'!E29,0) -> 3251.23 | G31: =IFERROR('Data Sheet'!F29,0) -> 4341.93 | H31: =IFERROR('Data Sheet'!G29,0) -> -2437.45 | I31: =IFERROR('Data Sheet'!H29,0) -> 395.25 | J31: =IFERROR('Data Sheet'!I29,0) -> 2541.86 | ... L31: =IFERROR('Data Sheet'!K29,0) -> 704.06 | M31: =IFERROR(SUM('Data Sheet'!H29:K29),0) -> 7872.46
B32: Effective Tax Rate | C32: =C31/C28 -> 0.25043888 | D32: =D31/D28 -> 0.36414699 | E32: =E31/E28 -> 0.18011192 | F32: =F31/F28 -> 0.43665933 | G32: =G31/G28 -> 0.83142102 | H32: =H31/H28 -> 0.52027791 | I32: =I31/I28 -> -0.037002572 | J32: =J31/J28 -> 3.9497475 | ... M32: =M31/M28 -> 0.19517825
B34: Net Profit | C34: =C28-C31 -> 14260.97 | D34: =D28-D31 -> 13345.62 | E34: =E28-E31 -> 13770.34 | F34: =F28-F31 -> 4194.46 | G34: =G28-G31 -> 880.37 | H34: =H28-H31 -> -2247.45 | I34: =I28-I31 -> -11076.94 | J34: =J28-J31 -> -1898.31 | ... M34: =M28-M31 -> 32462.26
B35: Net Margins | C35: =C34/C7 -> 0.061249606 | D35: =D34/D7 -> 0.050713147 | E35: =E34/E7 -> 0.050432382 | F35: =F34/F7 -> 0.015552749 | G35: =G34/G7 -> 0.0030196143 | H35: =H34/H7 -> -0.0074434057 | I35: =I34/I7 -> -0.042429334 | J35: =J34/J7 -> -0.0075994792 | ... M35: =M34/M7 -> 0.08079505
B37: Number of Equity Share | C37: =IFERROR('Data Sheet'!B93,0) -> 288.74 | D37: =IFERROR('Data Sheet'!C93,0) -> 288.74 | E37: =IFERROR('Data Sheet'!D93,0) -> 288.72 | F37: =IFERROR('Data Sheet'!E93,0) -> 288.73 | G37: =IFERROR('Data Sheet'!F93,0) -> 288.73 | H37: =IFERROR('Data Sheet'!G93,0) -> 288.73 | I37: =IFERROR('Data Sheet'!H93,0) -> 308.9 | J37: =IFERROR('Data Sheet'!I93,0) -> 332.03 | ... L37: =IFERROR('Data Sheet'!K93,0) -> 332.13
B39: EPS | C39: =IFERROR(C34/C37,0) -> 49.390351 | D39: =IFERROR(D34/D37,0) -> 46.220198 | E39: =IFERROR(E34/E37,0) -> 47.694444 | F39: =IFERROR(F34/F37,0) -> 14.527275 | G39: =IFERROR(G34/G37,0) -> 3.0491116 | H39: =IFERROR(H34/H37,0) -> -7.7839158 | I39: =IFERROR(I34/I37,0) -> -35.859307 | J39: =IFERROR(J34/J37,0) -> -5.7172846 | ... M39: =IFERROR(M34/M37,0) -> 0
B40: EPS Growth% | D40: =(D39/C39)-1 -> -0.064185676 | E40: =(E39/D39)-1 -> 0.031896149 | F40: =(F39/E39)-1 -> -0.6954095 | G40: =(G39/F39)-1 -> -0.79011124 | H40: =(H39/G39)-1 -> -3.5528471 | I40: =(I39/H39)-1 -> 3.6068468 | J40: =(J39/I39)-1 -> -0.84056344 | K40: =(K39/J39)-1 -> 6.194349 | ... M40: =(M39/L39)-1 -> -1
B42: Dividend Per Share | C42: =IFERROR('Data Sheet'!B31/'Historical FS'!C37,0) -> 2.2296183 | D42: =IFERROR('Data Sheet'!C31/'Historical FS'!D37,0) -> 0 | E42: =IFERROR('Data Sheet'!D31/'Historical FS'!E37,0) -> 0.23524522 | F42: =IFERROR('Data Sheet'!E31/'Historical FS'!F37,0) -> 0 | G42: =IFERROR('Data Sheet'!F31/'Historical FS'!G37,0) -> 0 | H42: =IFERROR('Data Sheet'!G31/'Historical FS'!H37,0) -> 0 | I42: =IFERROR('Data Sheet'!H31/'Historical FS'!I37,0) -> 0 | J42: =IFERROR('Data Sheet'!I31/'Historical FS'!J37,0) -> 0 | ... M42: =IFERROR('Data Sheet'!L31/'Historical FS'!M37,0) -> 0
B43: Dividend Payout Ratio | C43: =IFERROR(C42/C39,0) -> 0.045142792 | D43: =IFERROR(D42/D39,0) -> 0 | E43: =IFERROR(E42/E39,0) -> 0.0049323401 | F43: =IFERROR(F42/F39,0) -> 0 | G43: =IFERROR(G42/G39,0) -> 0 | H43: =IFERROR(H42/H39,0) -> 0 | I43: =IFERROR(I42/I39,0) -> 0 | J43: =IFERROR(J42/J39,0) -> 0 | ... M43: =IFERROR(M42/M39,0) -> 0
B45: Retained Earnings | C45: =IFERROR(IF(C39>C42,1-C43,0),0) -> 0.95485721 | D45: =IFERROR(IF(D39>D42,1-D43,0),0) -> 1 | E45: =IFERROR(IF(E39>E42,1-E43,0),0) -> 0.99506766 | F45: =IFERROR(IF(F39>F42,1-F43,0),0) -> 1 | G45: =IFERROR(IF(G39>G42,1-G43,0),0) -> 1 | H45: =IFERROR(IF(H39>H42,1-H43,0),0) -> 0 | I45: =IFERROR(IF(I39>I42,1-I43,0),0) -> 0 | J45: =IFERROR(IF(J39>J42,1-J43,0),0) -> 0 | ... M45: =IFERROR(IF(M39>M42,1-M43,0),0) -> 0
A47: # | B47: Balance Sheet
B48: Equity Share Capital | C48: =IFERROR('Data Sheet'!B57,0) -> 643.78 | D48: =IFERROR('Data Sheet'!C57,0) -> 643.78 | E48: =IFERROR('Data Sheet'!D57,0) -> 679.18 | F48: =IFERROR('Data Sheet'!E57,0) -> 679.22 | G48: =IFERROR('Data Sheet'!F57,0) -> 679.22 | H48: =IFERROR('Data Sheet'!G57,0) -> 679.22 | I48: =IFERROR('Data Sheet'!H57,0) -> 719.54 | J48: =IFERROR('Data Sheet'!I57,0) -> 765.81 | ... L48: =IFERROR('Data Sheet'!K57,0) -> 766.02
B49: Reserves | C49: =IFERROR('Data Sheet'!B58,0) -> 64959.67 | D49: =IFERROR('Data Sheet'!C58,0) -> 55618.14 | E49: =IFERROR('Data Sheet'!D58,0) -> 78273.23 | F49: =IFERROR('Data Sheet'!E58,0) -> 57382.67 | G49: =IFERROR('Data Sheet'!F58,0) -> 94748.69 | H49: =IFERROR('Data Sheet'!G58,0) -> 59500.34 | I49: =IFERROR('Data Sheet'!H58,0) -> 61491.49 | J49: =IFERROR('Data Sheet'!I58,0) -> 54480.91 | ... L49: =IFERROR('Data Sheet'!K58,0) -> 44555.77
B50: Borrowings | C50: =IFERROR('Data Sheet'!B59,0) -> 60642.28 | D50: =IFERROR('Data Sheet'!C59,0) -> 73610.39 | E50: =IFERROR('Data Sheet'!D59,0) -> 69359.96 | F50: =IFERROR('Data Sheet'!E59,0) -> 78603.98 | G50: =IFERROR('Data Sheet'!F59,0) -> 88950.47 | H50: =IFERROR('Data Sheet'!G59,0) -> 106175.34 | I50: =IFERROR('Data Sheet'!H59,0) -> 124787.64 | J50: =IFERROR('Data Sheet'!I59,0) -> 142130.57 | ... L50: =IFERROR('Data Sheet'!K59,0) -> 134113.44
B51: Other Liabilities | C51: =IFERROR('Data Sheet'!B60,0) -> 92180.26 | D51: =IFERROR('Data Sheet'!C60,0) -> 107442.48 | E51: =IFERROR('Data Sheet'!D60,0) -> 114871.75 | F51: =IFERROR('Data Sheet'!E60,0) -> 135914.49 | G51: =IFERROR('Data Sheet'!F60,0) -> 142813.43 | H51: =IFERROR('Data Sheet'!G60,0) -> 139348.59 | I51: =IFERROR('Data Sheet'!H60,0) -> 133180.72 | J51: =IFERROR('Data Sheet'!I60,0) -> 144192.62 | ... L51: =IFERROR('Data Sheet'!K60,0) -> 155239.2
B52: Total Liabilities | C52: =IFERROR('Data Sheet'!B61,0) -> 218425.99 | D52: =IFERROR('Data Sheet'!C61,0) -> 237314.79 | E52: =IFERROR('Data Sheet'!D61,0) -> 263184.12 | F52: =IFERROR('Data Sheet'!E61,0) -> 272580.36 | G52: =IFERROR('Data Sheet'!F61,0) -> 327191.81 | H52: =IFERROR('Data Sheet'!G61,0) -> 305703.49 | I52: =IFERROR('Data Sheet'!H61,0) -> 320179.39 | J52: =IFERROR('Data Sheet'!I61,0) -> 341569.91 | ... L52: =IFERROR('Data Sheet'!K61,0) -> 334674.43
B54: Fixed Assets - Net Block | C54: =IFERROR('Data Sheet'!B62,0) -> 69091.67 | D54: =IFERROR('Data Sheet'!C62,0) -> 88479.49 | E54: =IFERROR('Data Sheet'!D62,0) -> 107231.76 | F54: =IFERROR('Data Sheet'!E62,0) -> 95944.08 | G54: =IFERROR('Data Sheet'!F62,0) -> 121413.86 | H54: =IFERROR('Data Sheet'!G62,0) -> 111234.47 | I54: =IFERROR('Data Sheet'!H62,0) -> 127107.14 | J54: =IFERROR('Data Sheet'!I62,0) -> 138707.61 | ... L54: =IFERROR('Data Sheet'!K62,0) -> 132079.76
B55: Capital Work in Progress | C55: =IFERROR('Data Sheet'!B63,0) -> 33262.56 | D55: =IFERROR('Data Sheet'!C63,0) -> 28640.09 | E55: =IFERROR('Data Sheet'!D63,0) -> 25918.94 | F55: =IFERROR('Data Sheet'!E63,0) -> 33698.84 | G55: =IFERROR('Data Sheet'!F63,0) -> 40033.5 | H55: =IFERROR('Data Sheet'!G63,0) -> 31883.84 | I55: =IFERROR('Data Sheet'!H63,0) -> 35622.29 | J55: =IFERROR('Data Sheet'!I63,0) -> 20963.93 | ... L55: =IFERROR('Data Sheet'!K63,0) -> 14274.5
B56: Investments | C56: =IFERROR('Data Sheet'!B64,0) -> 10686.67 | D56: =IFERROR('Data Sheet'!C64,0) -> 15336.74 | E56: =IFERROR('Data Sheet'!D64,0) -> 23767.02 | F56: =IFERROR('Data Sheet'!E64,0) -> 20337.92 | G56: =IFERROR('Data Sheet'!F64,0) -> 20812.75 | H56: =IFERROR('Data Sheet'!G64,0) -> 15770.72 | I56: =IFERROR('Data Sheet'!H64,0) -> 16308.48 | J56: =IFERROR('Data Sheet'!I64,0) -> 24620.28 | ... L56: =IFERROR('Data Sheet'!K64,0) -> 26379.16
B57: Other Assets | C57: =IFERROR('Data Sheet'!B65-SUM('Data Sheet'!B67:B69),0) -> 37828.18 | D57: =IFERROR('Data Sheet'!C65-SUM('Data Sheet'!C67:C69),0) -> 30891.17 | E57: =IFERROR('Data Sheet'!D65-SUM('Data Sheet'!D67:D69),0) -> 29579.36 | F57: =IFERROR('Data Sheet'!E65-SUM('Data Sheet'!E67:E69),0) -> 37360.78 | G57: =IFERROR('Data Sheet'!F65-SUM('Data Sheet'!F67:F69),0) -> 48286.86 | H57: =IFERROR('Data Sheet'!G65-SUM('Data Sheet'!G67:G69),0) -> 56155.74 | I57: =IFERROR('Data Sheet'!H65-SUM('Data Sheet'!H67:H69),0) -> 58784.94 | J57: =IFERROR('Data Sheet'!I65-SUM('Data Sheet'!I67:I69),0) -> 61717.96 | ... L57: =IFERROR('Data Sheet'!K65-SUM('Data Sheet'!K67:K69),0) -> 68432.09
...

Sheet Ratio Analysis
B2: ='Data Sheet'!B1 -> TATA MOTORS LTD
B3: ="Ratio Analysis of - " & B2 -> Ratio Analysis of - TATA MOTORS LTD
B4: Years | C4: ='Data Sheet'!B16 -> 41729 | D4: ='Data Sheet'!C16 -> 42094 | E4: ='Data Sheet'!D16 -> 42460 | F4: ='Data Sheet'!E16 -> 42825 | G4: ='Data Sheet'!F16 -> 43190 | H4: ='Data Sheet'!G16 -> 43555 | I4: ='Data Sheet'!H16 -> 43921 | J4: ='Data Sheet'!I16 -> 44286 | ... L4: ='Data Sheet'!K16 -> 45016 | M4: TREND | N4: MEAN | O4: MEDIAN
B6: SalesGrowth | D6: =IFERROR('Historical FS'!D8,0) -> 0.13024457 | E6: =IFERROR('Historical FS'!E8,0) -> 0.037569001 | F6: =IFERROR('Historical FS'!F8,0) -> -0.01228033 | G6: =IFERROR('Historical FS'!G8,0) -> 0.081047746 | H6: =IFERROR('Historical FS'!H8,0) -> 0.035629919 | I6: =IFERROR('Historical FS'!I8,0) -> -0.13536016 | J6: =IFERROR('Historical FS'!J8,0) -> -0.043181168 | K6: =IFERROR('Historical FS'!K8,0) -> 0.11472967 | L6: =IFERROR('Historical FS'!L8,0) -> 0.24245815 | N6: =IFERROR(AVERAGE(D6:L6),0) -> 0.050095267 | O6: =IFERROR(MEDIAN(C6:L6),0) -> 0.037569001
B7: EBITDA Growth | D7: =IFERROR(('Historical FS'!D19/'Historical FS'!C19)-1,0) -> 0.12582115 | E7: =IFERROR(('Historical FS'!E19/'Historical FS'!D19)-1,0) -> -0.021494114 | F7: =IFERROR(('Historical FS'!F19/'Historical FS'!E19)-1,0) -> -0.22936587 | G7: =IFERROR(('Historical FS'!G19/'Historical FS'!F19)-1,0) -> 0.063165689 | H7: =IFERROR(('Historical FS'!H19/'Historical FS'!G19)-1,0) -> -0.21595203 | I7: =IFERROR(('Historical FS'!I19/'Historical FS'!H19)-1,0) -> -0.27072538 | J7: =IFERROR(('Historical FS'!J19/'Historical FS'!I19)-1,0) -> 0.79503554 | K7: =IFERROR(('Historical FS'!K19/'Historical FS'!J19)-1,0) -> -0.23437418 | L7: =IFERROR(('Historical FS'!L19/'Historical FS'!K19)-1,0) -> 0.28704224 | N7: =IFERROR(AVERAGE(D7:L7),0) -> 0.033239228 | O7: =IFERROR(MEDIAN(C7:L7),0) -> -0.021494114
B8: EBT Growth | D8: =IFERROR(('Historical FS'!D28/'Historical FS'!C28)-1,0) -> 0.10316382 | E8: =IFERROR(('Historical FS'!E28/'Historical FS'!D28)-1,0) -> -0.19978245 | F8: =IFERROR(('Historical FS'!F28/'Historical FS'!E28)-1,0) -> -0.55668252 | G8: =IFERROR(('Historical FS'!G28/'Historical FS'!F28)-1,0) -> -0.29861437 | H8: =IFERROR(('Historical FS'!H28/'Historical FS'!G28)-1,0) -> -1.8970951 | I8: =IFERROR(('Historical FS'!I28/'Historical FS'!H28)-1,0) -> 1.2800252 | J8: =IFERROR(('Historical FS'!J28/'Historical FS'!I28)-1,0) -> -1.060248 | K8: =IFERROR(('Historical FS'!K28/'Historical FS'!J28)-1,0) -> -15.649149 | L8: =IFERROR(('Historical FS'!L28/'Historical FS'!K28)-1,0) -> -0.65313669 | N8: =IFERROR(AVERAGE(D8:L8),0) -> -2.1035022 | O8: =IFERROR(MEDIAN(C8:L8),0) -> -0.55668252
B9: Net Profit Growth | D9: =IFERROR(('Historical FS'!D34/'Historical FS'!C34-1),0) -> -0.064185676 | E9: =IFERROR(('Historical FS'!E34/'Historical FS'!D34-1),0) -> 0.031824674 | F9: =IFERROR(('Historical FS'!F34/'Historical FS'!E34-1),0) -> -0.69539895 | G9: =IFERROR(('Historical FS'!G34/'Historical FS'!F34-1),0) -> -0.79011124 | H9: =IFERROR(('Historical FS'!H34/'Historical FS'!G34-1),0) -> -3.5528471 | I9: =IFERROR(('Historical FS'!I34/'Historical FS'!H34-1),0) -> 3.9286703 | J9: =IFERROR(('Historical FS'!J34/'Historical FS'!I34-1),0) -> -0.82862505 | K9: =IFERROR(('Historical FS'!K34/'Historical FS'!J34-1),0) -> 6.1952157 | L9: =IFERROR(('Historical FS'!L34/'Historical FS'!K34-1),0) -> -0.70904365 | N9: =IFERROR(AVERAGE(D9:L9),0) -> 0.390611 | O9: =IFERROR(MEDIAN(C9:L9),0) -> -0.69539895
B10: Dividend Growth | D10: =IFERROR(('Historical FS'!D42/'Historical FS'!C42)-1,0) -> -1 | E10: =IFERROR(('Historical FS'!E42/'Historical FS'!D42)-1,0) -> 0 | F10: =IFERROR(('Historical FS'!F42/'Historical FS'!E42)-1,0) -> -1 | G10: =IFERROR(('Historical FS'!G42/'Historical FS'!F42)-1,0) -> 0 | H10: =IFERROR(('Historical FS'!H42/'Historical FS'!G42)-1,0) -> 0 | I10: =IFERROR(('Historical FS'!I42/'Historical FS'!H42)-1,0) -> 0 | J10: =IFERROR(('Historical FS'!J42/'Historical FS'!I42)-1,0) -> 0 | K10: =IFERROR(('Historical FS'!K42/'Historical FS'!J42)-1,0) -> 0 | L10: =IFERROR(('Historical FS'!L42/'Historical FS'!K42)-1,0) -> 0 | N10: =IFERROR(AVERAGE(D10:L10),0) -> -0.22222222 | O10: =IFERROR(MEDIAN(C10:L10),0) -> 0
B12: Gross Margin | C12: =IFERROR('Historical FS'!C14,0) -> 0.22635301 | D12: =IFERROR('Historical FS'!D14,0) -> 0.22914703 | E12: =IFERROR('Historical FS'!E14,0) -> 0.24734524 | F12: =IFERROR('Historical FS'!F14,0) -> 0.23819078 | G12: =IFERROR('Historical FS'!G14,0) -> 0.2164999 | H12: =IFERROR('Historical FS'!H14,0) -> 0.19571167 | I12: =IFERROR('Historical FS'!I14,0) -> 0.19417127 | J12: =IFERROR('Historical FS'!J14,0) -> 0.21805386 | ... L12: =IFERROR('Historical FS'!L14,0) -> 0.20685018 | N12: =IFERROR(AVERAGE(C12:L12),0) -> 0.2170394 | O12: =IFERROR(MEDIAN(C12:L12),0) -> 0.21727688
B13: EBITDA Margin | C13: =IFERROR('Historical FS'!C20,0) -> 0.1496921 | D13: =IFERROR('Historical FS'!D20,0) -> 0.14910626 | E13: =IFERROR('Historical FS'!E20,0) -> 0.14061845 | F13: =IFERROR('Historical FS'!F20,0) -> 0.10971269 | G13: =IFERROR('Historical FS'!G20,0) -> 0.10789788 | H13: =IFERROR('Historical FS'!H20,0) -> 0.081686629 | I13: =IFERROR('Historical FS'!I20,0) -> 0.068898034 | J13: =IFERROR('Historical FS'!J20,0) -> 0.12925584 | ... L13: =IFERROR('Historical FS'!L20,0) -> 0.091961958 | N13: =IFERROR(AVERAGE(C13:L13),0) -> 0.11176062 | O13: =IFERROR(MEDIAN(C13:L13),0) -> 0.10880529
B14: EBIT Margin | C14: =IFERROR(('Historical FS'!C19-'Historical FS'!C25)/'Historical FS'!C7,0) -> 0.10211238 | D14: =IFERROR(('Historical FS'!D19-'Historical FS'!D25)/'Historical FS'!D7,0) -> 0.098229671 | E14: =IFERROR(('Historical FS'!E19-'Historical FS'!E25)/'Historical FS'!E7,0) -> 0.079417028 | F14: =IFERROR(('Historical FS'!F19-'Historical FS'!F25)/'Historical FS'!F7,0) -> 0.043322301 | G14: =IFERROR(('Historical FS'!G19-'Historical FS'!G25)/'Historical FS'!G7,0) -> 0.033970412 | H14: =IFERROR(('Historical FS'!H19-'Historical FS'!H25)/'Historical FS'!H7,0) -> 0.0035560233 | I14: =IFERROR(('Historical FS'!I19-'Historical FS'!I25)/'Historical FS'!I7,0) -> -0.013170363 | J14: =IFERROR(('Historical FS'!J19-'Historical FS'!J25)/'Historical FS'!J7,0) -> 0.034991608 | ... L14: =IFERROR(('Historical FS'!L19-'Historical FS'!L25)/'Historical FS'!L7,0) -> 0.020104347 | N14: =IFERROR(AVERAGE(C14:L14),0) -> 0.040211826 | O14: =IFERROR(MEDIAN(C14:L14),0) -> 0.03448101
B15: EBT Margin | C15: =IFERROR('Historical FS'!C29,0) -> 0.081713958 | D15: =IFERROR('Historical FS'!D29,0) -> 0.079756085 | E15: =IFERROR('Historical FS'!E29,0) -> 0.061511301 | F15: =IFERROR('Historical FS'!F29,0) -> 0.027608071 | G15: =IFERROR('Historical FS'!G29,0) -> 0.017912164 | H15: =IFERROR('Historical FS'!H29,0) -> -0.015516079 | I15: =IFERROR('Historical FS'!I29,0) -> -0.04091536 | J15: =IFERROR('Historical FS'!J29,0) -> 0.0025763152 | ... L15: =IFERROR('Historical FS'!L29,0) -> -0.009451885 | N15: =IFERROR(AVERAGE(C15:L15),0) -> 0.017133809 | O15: =IFERROR(MEDIAN(C15:L15),0) -> 0.01024424
B16: Net Profit Margin | C16: =IFERROR('Historical FS'!C35,0) -> 0.061249606 | D16: =IFERROR('Historical FS'!D35,0) -> 0.050713147 | E16: =IFERROR('Historical FS'!E35,0) -> 0.050432382 | F16: =IFERROR('Historical FS'!F35,0) -> 0.015552749 | G16: =IFERROR('Historical FS'!G35,0) -> 0.0030196143 | H16: =IFERROR('Historical FS'!H35,0) -> -0.0074434057 | I16: =IFERROR('Historical FS'!I35,0) -> -0.042429334 | J16: =IFERROR('Historical FS'!J35,0) -> -0.0075994792 | ... L16: =IFERROR('Historical FS'!L35,0) -> -0.011486935 | N16: =IFERROR(AVERAGE(C16:L16),0) -> 0.0062956191 | O16: =IFERROR(MEDIAN(C16:L16),0) -> -0.0022118957
B18: SalesExpenses%Sales | C18: =IFERROR('Historical FS'!C17,0) -> 0.076660909 | D18: =IFERROR('Historical FS'!D17,0) -> 0.08004078 | E18: =IFERROR('Historical FS'!E17,0) -> 0.10672679 | F18: =IFERROR('Historical FS'!F17,0) -> 0.1284781 | G18: =IFERROR('Historical FS'!G17,0) -> 0.10860202 | H18: =IFERROR('Historical FS'!H17,0) -> 0.11402505 | I18: =IFERROR('Historical FS'!I17,0) -> 0.12527324 | J18: =IFERROR('Historical FS'!J17,0) -> 0.088798023 | ... L18: =IFERROR('Historical FS'!L17,0) -> 0.11488822 | N18: =IFERROR(AVERAGE(C18:L18),0) -> 0.10527879 | O18: =IFERROR(MEDIAN(C18:L18),0) -> 0.10894839
B19: Depreciation%Sales | C19: =IFERROR('Historical FS'!C26,0) -> 0.047579718 | D19: =IFERROR('Historical FS'!D26,0) -> 0.050876584 | E19: =IFERROR('Historical FS'!E26,0) -> 0.061201426 | F19: =IFERROR('Historical FS'!F26,0) -> 0.066390387 | G19: =IFERROR('Historical FS'!G26,0) -> 0.073927472 | H19: =IFERROR('Historical FS'!H26,0) -> 0.078130605 | I19: =IFERROR('Historical FS'!I26,0) -> 0.082068398 | J19: =IFERROR('Historical FS'!J26,0) -> 0.094264231 | ... L19: =IFERROR('Historical FS'!L26,0) -> 0.071857611 | N19: =IFERROR(AVERAGE(C19:L19),0) -> 0.071548791 | O19: =IFERROR(MEDIAN(C19:L19),0) -> 0.072892542
B20: OperatingIncome%Sales | C20: =C14 -> 0.10211238 | D20: =D14 -> 0.098229671 | E20: =E14 -> 0.079417028 | F20: =F14 -> 0.043322301 | G20: =G14 -> 0.033970412 | H20: =H14 -> 0.0035560233 | I20: =I14 -> -0.013170363 | J20: =J14 -> 0.034991608 | ... L20: =L14 -> 0.020104347 | N20: =IFERROR(AVERAGE(C20:L20),0) -> 0.040211826 | O20: =IFERROR(MEDIAN(C20:L20),0) -> 0.03448101
B22: Return on Capital Employed | C22: =IFERROR(('Historical FS'!C19-'Historical FS'!C25)/('Historical FS'!C48+'Historical FS'!C49+'Historical FS'!C50),0) -> 0.18832479 | D22: =IFERROR(('Historical FS'!D19-'Historical FS'!D25)/('Historical FS'!D48+'Historical FS'!D49+'Historical FS'!D50),0) -> 0.19904181 | E22: =IFERROR(('Historical FS'!E19-'Historical FS'!E25)/('Historical FS'!E48+'Historical FS'!E49+'Historical FS'!E50),0) -> 0.1462081 | F22: =IFERROR(('Historical FS'!F19-'Historical FS'!F25)/('Historical FS'!F48+'Historical FS'!F49+'Historical FS'!F50),0) -> 0.085490986 | G22: =IFERROR(('Historical FS'!G19-'Historical FS'!G25)/('Historical FS'!G48+'Historical FS'!G49+'Historical FS'!G50),0) -> 0.053716114 | H22: =IFERROR(('Historical FS'!H19-'Historical FS'!H25)/('Historical FS'!H48+'Historical FS'!H49+'Historical FS'!H50),0) -> 0.0064542734 | I22: =IFERROR(('Historical FS'!I19-'Historical FS'!I25)/('Historical FS'!I48+'Historical FS'!I49+'Historical FS'!I50),0) -> -0.018387083 | J22: =IFERROR(('Historical FS'!J19-'Historical FS'!J25)/('Historical FS'!J48+'Historical FS'!J49+'Historical FS'!J50),0) -> 0.044284325 | ... L22: =IFERROR(('Historical FS'!L19-'Historical FS'!L25)/('Historical FS'!L48+'Historical FS'!L49+'Historical FS'!L50),0) -> 0.038762956 | N22: =IFERROR(AVERAGE(C22:L22),0) -> 0.074329107 | O22: =IFERROR(MEDIAN(C22:L22),0) -> 0.049000219
B23: Retained Earnings% | C23: =IFERROR('Historical FS'!C45,0) -> 0.95485721 | D23: =IFERROR('Historical FS'!D45,0) -> 1 | E23: =IFERROR('Historical FS'!E45,0) -> 0.99506766 | F23: =IFERROR('Historical FS'!F45,0) -> 1 | G23: =IFERROR('Historical FS'!G45,0) -> 1 | H23: =IFERROR('Historical FS'!H45,0) -> 0 | I23: =IFERROR('Historical FS'!I45,0) -> 0 | J23: =IFERROR('Historical FS'!J45,0) -> 0 | ... L23: =IFERROR('Historical FS'!L45,0) -> 0 | N23: =IFERROR(AVERAGE(C23:L23),0) -> 0.49499249 | O23: =IFERROR(MEDIAN(C23:L23),0) -> 0.4774286
B24: Return on Equity% | C24: =IFERROR('Historical FS'!C34/('Historical FS'!C48+'Historical FS'!C49),0) -> 0.2173814 | D24: =IFERROR('Historical FS'!D34/('Historical FS'!D48+'Historical FS'!D49),0) -> 0.2372052 | E24: =IFERROR('Historical FS'!E34/('Historical FS'!E48+'Historical FS'!E49),0) -> 0.17441317 | F24: =IFERROR('Historical FS'!F34/('Historical FS'!F48+'Historical FS'!F49),0) -> 0.07224119 | G24: =IFERROR('Historical FS'!G34/('Historical FS'!G48+'Historical FS'!G49),0) -> 0.0092254981 | H24: =IFERROR('Historical FS'!H34/('Historical FS'!H48+'Historical FS'!H49),0) -> -0.037345737 | I24: =IFERROR('Historical FS'!I34/('Historical FS'!I48+'Historical FS'!I49),0) -> -0.17805428 | J24: =IFERROR('Historical FS'!J34/('Historical FS'!J48+'Historical FS'!J49),0) -> -0.034360592 | ... L24: =IFERROR('Historical FS'!L34/('Historical FS'!L48+'Historical FS'!L49),0) -> -0.087686298 | N24: =IFERROR(AVERAGE(C24:L24),0) -> 0.0066503174 | O24: =IFERROR(MEDIAN(C24:L24),0) -> -0.012567547
B25: Self Sustained Growth Rate | C25: =C23*C24 -> 0.2075682 | D25: =D23*D24 -> 0.2372052 | E25: =E23*E24 -> 0.1735529 | F25: =F23*F24 -> 0.07224119 | G25: =G23*G24 -> 0.0092254981 | H25: =H23*H24 -> 0 | I25: =I23*I24 -> 0 | J25: =J23*J24 -> 0 | ... L25: =L23*L24 -> 0 | N25: =IFERROR(AVERAGE(C25:L25),0) -> 0.069979299 | O25: =IFERROR(MEDIAN(C25:L25),0) -> 0.004612749
B26: Interest Coverage Ratio | C26: =IFERROR(('Historical FS'!C19-'Historical FS'!C25)/'Historical FS'!C22,0) -> 5.0058954 | D26: =IFERROR(('Historical FS'!D19-'Historical FS'!D25)/'Historical FS'!D22,0) -> 5.317304 | E26: =IFERROR(('Historical FS'!E19-'Historical FS'!E25)/'Historical FS'!E22,0) -> 4.4352864 | F26: =IFERROR(('Historical FS'!F19-'Historical FS'!F25)/'Historical FS'!F22,0) -> 2.7568835 | G26: =IFERROR(('Historical FS'!G19-'Historical FS'!G25)/'Historical FS'!G22,0) -> 2.1154494 | H26: =IFERROR(('Historical FS'!H19-'Historical FS'!H25)/'Historical FS'!H22,0) -> 0.18645157 | I26: =IFERROR(('Historical FS'!I19-'Historical FS'!I25)/'Historical FS'!I22,0) -> -0.47469327 | J26: =IFERROR(('Historical FS'!J19-'Historical FS'!J25)/'Historical FS'!J22,0) -> 1.0794784 | ... L26: =IFERROR(('Historical FS'!L19-'Historical FS'!L25)/'Historical FS'!L22,0) -> 0.6802067 | N26: =IFERROR(AVERAGE(C26:L26),0) -> 2.1089848 | O26: =IFERROR(MEDIAN(C26:L26),0) -> 1.5974639
B28: Debtor Turnover Ratio | C28: =IFERROR('Historical FS'!C7/'Historical FS'!C60,0) -> 22.018971 | D28: =IFERROR('Historical FS'!D7/'Historical FS'!D60,0) -> 20.920168 | E28: =IFERROR('Historical FS'!E7/'Historical FS'!E60,0) -> 20.119918 | F28: =IFERROR('Historical FS'!F7/'Historical FS'!F60,0) -> 19.160353 | G28: =IFERROR('Historical FS'!G7/'Historical FS'!G60,0) -> 14.655712 | H28: =IFERROR('Historical FS'!H7/'Historical FS'!H60,0) -> 15.894699 | I28: =IFERROR('Historical FS'!I7/'Historical FS'!I60,0) -> 23.366617 | J28: =IFERROR('Historical FS'!J7/'Historical FS'!J60,0) -> 19.701331 | ... L28: =IFERROR('Historical FS'!L7/'Historical FS'!L60,0) -> 21.982948 | N28: =IFERROR(AVERAGE(C28:L28),0) -> 20.020063 | O28: =IFERROR(MEDIAN(C28:L28),0) -> 20.520043
B29: Creditor Turnover Ratio | C29: =IFERROR('Historical FS'!C7/'Historical FS'!C51,0) -> 2.5258516 | D29: =IFERROR('Historical FS'!D7/'Historical FS'!D51,0) -> 2.4493011 | E29: =IFERROR('Historical FS'!E7/'Historical FS'!E51,0) -> 2.3769604 | F29: =IFERROR('Historical FS'!F7/'Historical FS'!F51,0) -> 1.9842808 | G29: =IFERROR('Historical FS'!G7/'Historical FS'!G51,0) -> 2.041478 | H29: =IFERROR('Historical FS'!H7/'Historical FS'!H51,0) -> 2.1667848 | I29: =IFERROR('Historical FS'!I7/'Historical FS'!I51,0) -> 1.9602535 | J29: =IFERROR('Historical FS'!J7/'Historical FS'!J51,0) -> 1.7323685 | ... L29: =IFERROR('Historical FS'!L7/'Historical FS'!L51,0) -> 2.2286057 | N29: =IFERROR(AVERAGE(C29:L29),0) -> 2.1482916 | O29: =IFERROR(MEDIAN(C29:L29),0) -> 2.1041314
B30: Inventory Turnover | C30: =IFERROR('Historical FS'!C7/'Historical FS'!C61,0) -> 8.5378094 | D30: =IFERROR('Historical FS'!D7/'Historical FS'!D61,0) -> 8.990022 | E30: =IFERROR('Historical FS'!E7/'Historical FS'!E61,0) -> 8.3613381 | F30: =IFERROR('Historical FS'!F7/'Historical FS'!F61,0) -> 7.6867643 | G30: =IFERROR('Historical FS'!G7/'Historical FS'!G61,0) -> 6.9190052 | H30: =IFERROR('Historical FS'!H7/'Historical FS'!H61,0) -> 7.7392856 | I30: =IFERROR('Historical FS'!I7/'Historical FS'!I61,0) -> 6.9698269 | J30: =IFERROR('Historical FS'!J7/'Historical FS'!J61,0) -> 6.9217099 | ... L30: =IFERROR('Historical FS'!L7/'Historical FS'!L61,0) -> 8.4888642 | N30: =IFERROR(AVERAGE(C30:L30),0) -> 7.8516184 | O30: =IFERROR(MEDIAN(C30:L30),0) -> 7.8204222
B31: Fixed Asset Turnover | C31: =IFERROR('Historical FS'!C7/'Historical FS'!C54,0) -> 3.3699238 | D31: =IFERROR('Historical FS'!D7/'Historical FS'!D54,0) -> 2.9742371 | E31: =IFERROR('Historical FS'!E7/'Historical FS'!E54,0) -> 2.5463128 | F31: =IFERROR('Historical FS'!F7/'Historical FS'!F54,0) -> 2.8109343 | G31: =IFERROR('Historical FS'!G7/'Historical FS'!G54,0) -> 2.4012949 | H31: =IFERROR('Historical FS'!H7/'Historical FS'!H54,0) -> 2.714432 | I31: =IFERROR('Historical FS'!I7/'Historical FS'!I54,0) -> 2.0539206 | J31: =IFERROR('Historical FS'!J7/'Historical FS'!J54,0) -> 1.8008727 | ... L31: =IFERROR('Historical FS'!L7/'Historical FS'!L54,0) -> 2.6193792 | N31: =IFERROR(AVERAGE(C31:L31),0) -> 2.5296656 | O31: =IFERROR(MEDIAN(C31:L31),0) -> 2.582846
B32: Capital Turnover Ratio | C32: =IFERROR('Historical FS'!C7/('Historical FS'!C48+'Historical FS'!C49),0) -> 3.5491069 | D32: =IFERROR('Historical FS'!D7/('Historical FS'!D48+'Historical FS'!D49),0) -> 4.6773907 | E32: =IFERROR('Historical FS'!E7/('Historical FS'!E48+'Historical FS'!E49),0) -> 3.4583567 | F32: =IFERROR('Historical FS'!F7/('Historical FS'!F48+'Historical FS'!F49),0) -> 4.6449144 | G32: =IFERROR('Historical FS'!G7/('Historical FS'!G48+'Historical FS'!G49),0) -> 3.0551909 | H32: =IFERROR('Historical FS'!H7/('Historical FS'!H48+'Historical FS'!H49),0) -> 5.0172916 | I32: =IFERROR('Historical FS'!I7/('Historical FS'!I48+'Historical FS'!I49),0) -> 4.1964901 | J32: =IFERROR('Historical FS'!J7/('Historical FS'!J48+'Historical FS'!J49),0) -> 4.5214404 | ... L32: =IFERROR('Historical FS'!L7/('Historical FS'!L48+'Historical FS'!L49),0) -> 7.6335681 | N32: =IFERROR(AVERAGE(C32:L32),0) -> 4.7002535 | O32: =IFERROR(MEDIAN(C32:L32),0) -> 4.5831774
B34: (in days)
B35: Debtor Days | C35: =IFERROR(365/C28,0) -> 16.576615 | D35: =IFERROR(365/D28,0) -> 17.447278 | E35: =IFERROR(365/E28,0) -> 18.141227 | F35: =IFERROR(365/F28,0) -> 19.049753 | G35: =IFERROR(365/G28,0) -> 24.904965 | H35: =IFERROR(365/H28,0) -> 22.963631 | I35: =IFERROR(365/I28,0) -> 15.620575 | J35: =IFERROR(365/J28,0) -> 18.526667 | ... L35: =IFERROR(365/L28,0) -> 16.603779 | N35: =IFERROR(AVERAGE(C35:L35),0) -> 18.614376 | O35: =IFERROR(MEDIAN(C35:L35),0) -> 17.794253
B36: Payable Days | C36: =IFERROR(365/C29,0) -> 144.50572 | D36: =IFERROR(365/D29,0) -> 149.02211 | E36: =IFERROR(365/E29,0) -> 153.55746 | F36: =IFERROR(365/F29,0) -> 183.94574 | G36: =IFERROR(365/G29,0) -> 178.79203 | H36: =IFERROR(365/H29,0) -> 168.45236 | I36: =IFERROR(365/I29,0) -> 186.20041 | J36: =IFERROR(365/J29,0) -> 210.69421 | ... L36: =IFERROR(365/L29,0) -> 163.77953 | N36: =IFERROR(AVERAGE(C36:L36),0) -> 171.99086 | O36: =IFERROR(MEDIAN(C36:L36),0) -> 173.62219
B37: Inventory Days | C37: =IFERROR(365/C30,0) -> 42.751013 | D37: =IFERROR(365/D30,0) -> 40.600568 | E37: =IFERROR(365/E30,0) -> 43.6533 | F37: =IFERROR(365/F30,0) -> 47.484219 | G37: =IFERROR(365/G30,0) -> 52.753249 | H37: =IFERROR(365/H30,0) -> 47.161976 | I37: =IFERROR(365/I30,0) -> 52.368589 | J37: =IFERROR(365/J30,0) -> 52.732635 | ... L37: =IFERROR(365/L30,0) -> 42.997507 | N37: =IFERROR(AVERAGE(C37:L37),0) -> 46.869647 | O37: =IFERROR(MEDIAN(C37:L37),0) -> 46.677696
B38: Cash Conversion Cycle (in days) | C38: =(C35+C37)-C36 -> -85.178089 | D38: =(D35+D37)-D36 -> -90.974259 | E38: =(E35+E37)-E36 -> -91.762933 | F38: =(F35+F37)-F36 -> -117.41177 | G38: =(G35+G37)-G36 -> -101.13382 | H38: =(H35+H37)-H36 -> -98.326751 | I38: =(I35+I37)-I36 -> -118.21124 | J38: =(J35+J37)-J36 -> -139.4349 | ... L38: =(L35+L37)-L36 -> -104.17824 | N38: =IFERROR(AVERAGE(C38:L38),0) -> -106.50684 | O38: =IFERROR(MEDIAN(C38:L38),0) -> -102.65603
B40: CFO/Sales | C40: =IFERROR('Historical FS'!C71/'Historical FS'!C7,0) -> 0.15526604 | D40: =IFERROR('Historical FS'!D71/'Historical FS'!D7,0) -> 0.13501823 | E40: =IFERROR('Historical FS'!E71/'Historical FS'!E7,0) -> 0.13880297 | F40: =IFERROR('Historical FS'!F71/'Historical FS'!F7,0) -> 0.1119766 | G40: =IFERROR('Historical FS'!G71/'Historical FS'!G7,0) -> 0.081829466 | H40: =IFERROR('Historical FS'!H71/'Historical FS'!H7,0) -> 0.062564914 | I40: =IFERROR('Historical FS'!I71/'Historical FS'!I7,0) -> 0.10201535 | J40: =IFERROR('Historical FS'!J71/'Historical FS'!J7,0) -> 0.11609736 | ... L40: =IFERROR('Historical FS'!L71/'Historical FS'!L7,0) -> 0.10228725 | N40: =IFERROR(AVERAGE(C40:L40),0) -> 0.10571516 | O40: =IFERROR(MEDIAN(C40:L40),0) -> 0.10713192
B41: CFO/Total Assets | C41: =IFERROR('Historical FS'!C71/'Historical FS'!C65,0) -> 0.16550759 | D41: =IFERROR('Historical FS'!D71/'Historical FS'!D65,0) -> 0.14972206 | E41: =IFERROR('Historical FS'!E71/'Historical FS'!E65,0) -> 0.1440039 | F41: =IFERROR('Historical FS'!F71/'Historical FS'!F65,0) -> 0.11079026 | G41: =IFERROR('Historical FS'!G71/'Historical FS'!G65,0) -> 0.0729157 | H41: =IFERROR('Historical FS'!H71/'Historical FS'!H65,0) -> 0.061794355 | I41: =IFERROR('Historical FS'!I71/'Historical FS'!I65,0) -> 0.083181307 | J41: =IFERROR('Historical FS'!J71/'Historical FS'!J65,0) -> 0.084903585 | ... L41: =IFERROR('Historical FS'!L71/'Historical FS'!L65,0) -> 0.10573861 | N41: =IFERROR(AVERAGE(C41:L41),0) -> 0.10219621 | O41: =IFERROR(MEDIAN(C41:L41),0) -> 0.095321099
B42: CFO/Total Debt | C42: =IFERROR('Historical FS'!C71/'Historical FS'!C50,0) -> 0.59613788 | D42: =IFERROR('Historical FS'!D71/'Historical FS'!D50,0) -> 0.48269354 | E42: =IFERROR('Historical FS'!E71/'Historical FS'!E50,0) -> 0.54641814 | F42: =IFERROR('Historical FS'!F71/'Historical FS'!F50,0) -> 0.38419492 | G42: =IFERROR('Historical FS'!G71/'Historical FS'!G50,0) -> 0.26821016 | H42: =IFERROR('Historical FS'!H71/'Historical FS'!H50,0) -> 0.17792032 | I42: =IFERROR('Historical FS'!I71/'Historical FS'!I50,0) -> 0.21342611 | J42: =IFERROR('Historical FS'!J71/'Historical FS'!J50,0) -> 0.20404133 | ... L42: =IFERROR('Historical FS'!L71/'Historical FS'!L50,0) -> 0.26386625 | N42: =IFERROR(AVERAGE(C42:L42),0) -> 0.32344363 | O42: =IFERROR(MEDIAN(C42:L42),0) -> 0.2660382

Sheet Forecast
B3: ='Data Sheet'!$B$1 & " - " & 'Data Sheet'!A17 & " Forecasting" -> TATA MOTORS LTD - Sales Forecasting | G3: ='Data Sheet'!$B$1 & " - " & 'Historical FS'!B19 & " Forecasting" -> TATA MOTORS LTD - EBITDA Forecasting | L3: ='Data Sheet'!$B$1&" - "& 'Historical FS'!B39 &" Forecasting" -> TATA MOTORS LTD - EPS Forecasting
B4: Year Weight | C4: Year | D4: Sales | E4: Sales Growth | G4: Year Weight | H4: Year | I4: EBITDA | J4: EBITDA Growth | L4: Year Weight | M4: Year | N4: EPS | O4: EPS Growth
B5: 1 | C5: =YEAR('Data Sheet'!B16) -> 2014 | D5: {=TRANSPOSE('Historical FS'!C7:L7)} -> 232833.66 | G5: 1 | H5: =C5 -> 2014 | I5: {=TRANSPOSE('Historical FS'!C19:L19)} -> 34853.36 | L5: 1 | M5: =H5 -> 2014 | N5: {=TRANSPOSE('Historical FS'!C39:L39)} -> 49.390351
B6: =B5+1 -> 2 | C6: =C5+1 -> 2015 | D6: 263158.98 | E6: =(D6/D5)-1 -> 0.13024457 | G6: =G5+1 -> 2 | H6: =H5+1 -> 2015 | I6: 39238.65 | J6: =(I6/I5)-1 -> 0.12582115 | L6: =L5+1 -> 2 | M6: =M5+1 -> 2015 | N6: 46.220198 | O6: =(N6/N5)-1 -> -0.064185676
B7: =B6+1 -> 3 | C7: =C6+1 -> 2016 | D7: 273045.6 | E7: =(D7/D6)-1 -> 0.037569001 | G7: =G6+1 -> 3 | H7: =H6+1 -> 2016 | I7: 38395.25 | J7: =(I7/I6)-1 -> -0.021494114 | L7: =L6+1 -> 3 | M7: =M6+1 -> 2016 | N7: 47.694444 | O7: =(N7/N6)-1 -> 0.031896149
B8: =B7+1 -> 4 | C8: =C7+1 -> 2017 | D8: 269692.51 | E8: =(D8/D7)-1 -> -0.01228033 | G8: =G7+1 -> 4 | H8: =H7+1 -> 2017 | I8: 29588.69 | J8: =(I8/I7)-1 -> -0.22936587 | L8: =L7+1 -> 4 | M8: =M7+1 -> 2017 | N8: 14.527275 | O8: =(N8/N7)-1 -> -0.6954095
B9: =B8+1 -> 5 | C9: =C8+1 -> 2018 | D9: 291550.48 | E9: =(D9/D8)-1 -> 0.081047746 | G9: =G8+1 -> 5 | H9: =H8+1 -> 2018 | I9: 31457.68 | J9: =(I9/I8)-1 -> 0.063165689 | L9: =L8+1 -> 5 | M9: =M8+1 -> 2018 | N9: 3.0491116 | O9: =(N9/N8)-1 -> -0.79011124
B10: =B9+1 -> 6 | C10: =C9+1 -> 2019 | D10: 301938.4 | E10: =(D10/D9)-1 -> 0.035629919 | G10: =G9+1 -> 6 | H10: =H9+1 -> 2019 | I10: 24664.33 | J10: =(I10/I9)-1 -> -0.21595203 | L10: =L9+1 -> 6 | M10: =M9+1 -> 2019 | N10: -7.7839158 | O10: =(N10/N9)-1 -> -3.5528471
B11: =B10+1 -> 7 | C11: =C10+1 -> 2020 | D11: 261067.97 | E11: =(D11/D10)-1 -> -0.13536016 | G11: =G10+1 -> 7 | H11: =H10+1 -> 2020 | I11: 17987.07 | J11: =(I11/I10)-1 -> -0.27072538 | L11: =L10+1 -> 7 | M11: =M10+1 -> 2020 | N11: -35.859307 | O11: =(N11/N10)-1 -> 3.6068468
B12: =B11+1 -> 8 | C12: =C11+1 -> 2021 | D12: 249794.75 | E12: =(D12/D11)-1 -> -0.043181168 | G12: =G11+1 -> 8 | H12: =H11+1 -> 2021 | I12: 32287.43 | J12: =(I12/I11)-1 -> 0.79503554 | L12: =L11+1 -> 8 | M12: =M11+1 -> 2021 | N12: -5.7172846 | O12: =(N12/N11)-1 -> -0.84056344
B13: =B12+1 -> 9 | C13: =C12+1 -> 2022 | D13: 278453.62 | E13: =(D13/D12)-1 -> 0.11472967 | G13: =G12+1 -> 9 | H13: =H12+1 -> 2022 | I13: 24720.09 | J13: =(I13/I12)-1 -> -0.23437418 | L13: =L12+1 -> 9 | M13: =M12+1 -> 2022 | N13: -41.132141 | O13: =(N13/N12)-1 -> 6.194349
B14: =B13+1 -> 10 | C14: =C13+1 -> 2023 | D14: 345966.97 | E14: =(D14/D13)-1 -> 0.24245815 | G14: =G13+1 -> 10 | H14: =H13+1 -> 2023 | I14: 31815.8 | J14: =(I14/I13)-1 -> 0.28704224 | L14: =L13+1 -> 10 | M14: =M13+1 -> 2023 | N14: -11.965495 | O14: =(N14/N13)-1 -> -0.70909622
B15: =B14+1 -> 11 | C15: =C14+1 -> 2024 | D15: =FORECAST(B15,$D$5:$D$14,$B$5:$B$14) -> 309867.7 | E15: =(D15/D14)-1 -> -0.1043431 | G15: =G14+1 -> 11 | H15: =H14+1 -> 2024 | I15: =FORECAST(G15,$I$5:$I$14,$G$5:$G$14) -> 23797.326 | J15: =(I15/I14)-1 -> -0.25202805 | L15: =L14+1 -> 11 | M15: =M14+1 -> 2024 | N15: =FORECAST(L15,$N$5:$N$14,$L$5:$L$14) -> -47.248357 | O15: =(N15/N14)-1 -> 2.9487171
B16: =B15+1 -> 12 | C16: =C15+1 -> 2025 | D16: =FORECAST(B16,$D$5:$D$14,$B$5:$B$14) -> 315889.05 | E16: =(D16/D15)-1 -> 0.019431994 | G16: =G15+1 -> 12 | H16: =H15+1 -> 2025 | I16: =FORECAST(G16,$I$5:$I$14,$G$5:$G$14) -> 22578.506 | J16: =(I16/I15)-1 -> -0.051216671 | L16: =L15+1 -> 12 | M16: =M15+1 -> 2025 | N16: =FORECAST(L16,$N$5:$N$14,$L$5:$L$14) -> -56.901208 | O16: =(N16/N15)-1 -> 0.20430025
B17: =B16+1 -> 13 | C17: =C16+1 -> 2026 | D17: =FORECAST(B17,$D$5:$D$14,$B$5:$B$14) -> 321910.4 | E17: =(D17/D16)-1 -> 0.019061589 | G17: =G16+1 -> 13 | H17: =H16+1 -> 2026 | I17: =FORECAST(G17,$I$5:$I$14,$G$5:$G$14) -> 21359.686 | J17: =(I17/I16)-1 -> -0.05398142 | L17: =L16+1 -> 13 | M17: =M16+1 -> 2026 | N17: =FORECAST(L17,$N$5:$N$14,$L$5:$L$14) -> -66.554059 | O17: =(N17/N16)-1 -> 0.16964229
B18: =B17+1 -> 14 | C18: =C17+1 -> 2027 | D18: =FORECAST(B18,$D$5:$D$14,$B$5:$B$14) -> 327931.75 | E18: =(D18/D17)-1 -> 0.018705042 | G18: =G17+1 -> 14 | H18: =H17+1 -> 2027 | I18: =FORECAST(G18,$I$5:$I$14,$G$5:$G$14) -> 20140.867 | J18: =(I18/I17)-1 -> -0.057061691 | L18: =L17+1 -> 14 | M18: =M17+1 -> 2027 | N18: =FORECAST(L18,$N$5:$N$14,$L$5:$L$14) -> -76.20691 | O18: =(N18/N17)-1 -> 0.14503775
B19: =B18+1 -> 15 | C19: =C18+1 -> 2028 | D19: =FORECAST(B19,$D$5:$D$14,$B$5:$B$14) -> 333953.09 | E19: =(D19/D18)-1 -> 0.018361587 | G19: =G18+1 -> 15 | H19: =H18+1 -> 2028 | I19: =FORECAST(G19,$I$5:$I$14,$G$5:$G$14) -> 18922.047 | J19: =(I19/I18)-1 -> -0.060514766 | L19: =L18+1 -> 15 | M19: =M18+1 -> 2028 | N19: =FORECAST(L19,$N$5:$N$14,$L$5:$L$14) -> -85.859761 | O19: =(N19/N18)-1 -> 0.12666635

Sheet Data>

Sheet Data Sheet
A1: COMPANY NAME | B1: TATA MOTORS LTD | E1: =IF(B2<>B3, "A NEW VERSION OF THE WORKSHEET IS AVAILABLE", "")
A2: LATEST VERSION | B2: 2.1 | E2: PLEASE DO NOT MAKE ANY CHANGES TO THIS SHEET
A3: CURRENT VERSION | B3: 2.1
A5: META
A6: Number of shares | B6: =IF(B9>0, B9/B8, 0) -> 366.52656
A7: Face Value | B7: 2
A8: Current Price | B8: 705.45
A9: Market Capitalization | B9: 258566.16
A15: PROFIT & LOSS
A16: Report Date | B16: 41729 | C16: 42094 | D16: 42460 | E16: 42825 | F16: 43190 | G16: 43555 | H16: 43921 | I16: 44286 | J16: 44651 | K16: 45016
A17: Sales | B17: 232833.66 | C17: 263158.98 | D17: 273045.6 | E17: 269692.51 | F17: 291550.48 | G17: 301938.4 | H17: 261067.97 | I17: 249794.75 | J17: 278453.62 | K17: 345966.97
A18: Raw Material Cost | B18: 146426.99 | C18: 163250.36 | D18: 166134.01 | E18: 173294.08 | F18: 187896.58 | G18: 194267.91 | H18: 164899.82 | I18: 153607.36 | J18: 179295.33 | K18: 231251.26
A19: Change in Inventory | B19: 2840.58 | C19: 3330.35 | D19: 2750.99 | E19: 7399.92 | F19: 2046.58 | G19: -2053.28 | H19: -2231.19 | I19: -4684.16 | J19: -1590.49 | K19: 4781.62
A20: Power and Fuel | B20: 1128.69 | C20: 1121.75 | D20: 1143.63 | E20: 1159.82 | F20: 1308.08 | G20: 1585.93 | H20: 1264.95 | I20: 1112.87 | J20: 2178.29 | K20: 2513.33
A21: Other Mfr. Exp | B21: 13806.04 | C21: 16173.17 | D21: 12101.53 | E21: 10067.37 | F21: 10971.66 | G21: 11694.54 | H21: 11541.51 | I21: 8273.17 | J21: 9427.38 | K21: 11765.97
A22: Employee Cost | B22: 21609.92 | C22: 25641.95 | D22: 28880.89 | E22: 28332.89 | F22: 30300.09 | G22: 33243.87 | H22: 30438.6 | I22: 27648.48 | J22: 30808.52 | K22: 33654.7
A23: Selling and admin | B23: 22357.79 | C23: 23603.01 | D23: 21991.9 | E23: 30039.38 | F23: 31004.58 | G23: 32719.8 | H23: 29248.32 | I23: 23015.79 | J23: 29205.4 | K23: 34839.19
A24: Other Expenses | B24: -4508.55 | C24: -2539.56 | D24: 7149.38 | E24: 4610.2 | F24: 658.39 | G24: 1708.74 | H24: 3456.51 | I24: -834.51 | J24: 1228.12 | K24: 4908.34
A25: Other Income | B25: -156.79 | C25: 714.03 | D25: -2669.62 | E25: 1869.1 | F25: 5932.73 | G25: -26686.25 | H25: 101.71 | I25: -11117.83 | J25: 2424.05 | K25: 6327.59
A26: Depreciation | B26: 11078.16 | C26: 13388.63 | D26: 16710.78 | E26: 17904.99 | F26: 21553.59 | G26: 23590.63 | H26: 21425.43 | I26: 23546.71 | J26: 24835.69 | K26: 24860.36
A27: Interest | B27: 4749.44 | C27: 4861.49 | D27: 4889.08 | E27: 4238.01 | F27: 4681.79 | G27: 5758.6 | H27: 7243.33 | I27: 8097.17 | J27: 9311.86 | K27: 10225.48
... A30: Net profit | B30: 13991.02 | C30: 13986.29 | D30: 11579.31 | E30: 7454.36 | F30: 8988.91 | G30: -28826.23 | H30: -12070.85 | I30: -13451.39 | J30: -11441.47 | K30: 2414.29
A31: Dividend Amount | B31: 643.78 | D31: 67.92 | K31: 766.02
A40: Quarters
A41: Report Date | B41: 44377 | C41: 44469 | D41: 44561 | E41: 44651 | F41: 44742 | G41: 44834 | H41: 44926 | I41: 45016 | J41: 45107 | K41: 45199
A42: Sales | B42: 66406.45 | C42: 61378.82 | D42: 72229.29 | E42: 78439.06 | F42: 71934.66 | G42: 79611.37 | H42: 88488.59 | I42: 105932.35 | J42: 102236.08 | K42: 105128.24
A43: Expenses | B43: 61163.78 | C43: 57262.21 | D43: 65151.27 | E43: 70156.27 | F43: 69521.93 | G43: 74039.06 | H43: 77668.35 | I43: 92817.95 | J43: 89018.36 | K43: 91361.3
A44: Other Income | B44: 584.12 | C44: 862.46 | D44: 788.73 | E44: 188.74 | F44: 2380.98 | G44: 1351.14 | H44: 1129.98 | I44: 1361.61 | J44: 683.56 | K44: 1507.05
A45: Depreciation | B45: 6202.13 | C45: 6123.32 | D45: 6078.13 | E45: 6432.11 | F45: 5841.04 | G45: 5897.34 | H45: 6071.78 | I45: 7050.2 | J45: 6633.18 | K45: 6636.42
A46: Interest | B46: 2203.3 | C46: 2327.3 | D46: 2400.74 | E46: 2380.52 | F46: 2420.72 | G46: 2487.26 | H46: 2675.83 | I46: 2641.67 | J46: 2615.39 | K46: 2651.69
A47: Profit before tax | B47: -2578.64 | C47: -3471.55 | D47: -612.12 | E47: -341.1 | F47: -3468.05 | G47: -1461.15 | H47: 3202.61 | I47: 4784.14 | J47: 4652.71 | K47: 5985.88
A48: Tax | B48: 1741.96 | C48: 1005.06 | D48: 726.05 | E48: 758.22 | F48: 1518.96 | G48: -457.08 | H48: 262.83 | I48: -620.65 | J48: 1563.01 | K48: 2202.84
A49: Net profit | B49: -4450.92 | C49: -4441.57 | D49: -1516.14 | E49: -1032.84 | F49: -5006.6 | G49: -944.61 | H49: 2957.71 | I49: 5407.79 | J49: 3202.8 | K49: 3764
A50: Operating Profit | B50: 5242.67 | C50: 4116.61 | D50: 7078.02 | E50: 8282.79 | F50: 2412.73 | G50: 5572.31 | H50: 10820.24 | I50: 13114.4 | J50: 13217.72 | K50: 13766.94
A55: BALANCE SHEET
A56: Report Date | B56: 41729 | C56: 42094 | D56: 42460 | E56: 42825 | F56: 43190 | G56: 43555 | H56: 43921 | I56: 44286 | J56: 44651 | K56: 45016
A57: Equity Share Capital | B57: 643.78 | C57: 643.78 | D57: 679.18 | E57: 679.22 | F57: 679.22 | G57: 679.22 | H57: 719.54 | I57: 765.81 | J57: 765.88 | K57: 766.02
A58: Reserves | B58: 64959.67 | C58: 55618.14 | D58: 78273.23 | E58: 57382.67 | F58: 94748.69 | G58: 59500.34 | H58: 61491.49 | I58: 54480.91 | J58: 43795.36 | K58: 44555.77
A59: Borrowings | B59: 60642.28 | C59: 73610.39 | D59: 69359.96 | E59: 78603.98 | F59: 88950.47 | G59: 106175.34 | H59: 124787.64 | I59: 142130.57 | J59: 146449.03 | K59: 134113.44
A60: Other Liabilities | B60: 92180.26 | C60: 107442.48 | D60: 114871.75 | E60: 135914.49 | F60: 142813.43 | G60: 139348.59 | H60: 133180.72 | I60: 144192.62 | J60: 138051.22 | K60: 155239.2
...

Sheet NOTES

Sheet RATIO and Forecast
B1: # cash Flow has been borrowed from the data sheet only for the sake of simplicity.
B2: #Ratio analysis notes =>
C7: 1. Set in the format of X by using the following -
C8: 2. Trend line by Spark Line.
B18: # Forecast (in forecast we choose regression instead of Arithmetic in Geometric Mean since in them analysis fails when the growth rate of the thing to be forecasted in uneven)
B19: (Regression line is the line closest to all the known Data Points.)
B20: Copy year and sales data from screener and transpose it by ctrl alt v => text => transpose
F29: By using custom format 0 "A" in ctrl+1
B41: # Comprehensive Forecast
J43: Take year and sales array => insert scatter diagram => add chart element "trendline"
I55: By Data
I56: .=>"Data analysis"

Sheet Comp Forecast Sheet
B2: Through Regression
B3: TATA MOTORS LTD.
B4: Year Weight | C4: Year | D4: Sales | E4: Sales Growth
B5: 1 | C5: 2012 | D5: 165654
B6: =B5+1 -> 2 | C6: =C5+1 -> 2013 | D6: 188793 | E6: =(D6/D5)-1 -> 0.13968271
B7: =B6+1 -> 3 | C7: =C6+1 -> 2014 | D7: 232834 | E7: =(D7/D6)-1 -> 0.23327666
B8: =B7+1 -> 4 | C8: =C7+1 -> 2015 | D8: 263159 | E8: =(D8/D7)-1 -> 0.13024301
B9: =B8+1 -> 5 | C9: =C8+1 -> 2016 | D9: 273046 | E9: =(D9/D8)-1 -> 0.037570442
B10: =B9+1 -> 6 | C10: =C9+1 -> 2017 | D10: 269693 | E10: =(D10/D9)-1 -> -0.012279982
B11: =B10+1 -> 7 | C11: =C10+1 -> 2018 | D11: 291550 | E11: =(D11/D10)-1 -> 0.081044002
B12: =B11+1 -> 8 | C12: =C11+1 -> 2019 | D12: 301938 | E12: =(D12/D11)-1 -> 0.035630252
B13: =B12+1 -> 9 | C13: =C12+1 -> 2020 | D13: 261068 | E13: =(D13/D12)-1 -> -0.13535891
B14: =B13+1 -> 10 | C14: =C13+1 -> 2021 | D14: 249795 | E14: =(D14/D13)-1 -> -0.043180321
B15: =B14+1 -> 11 | C15: =C14+1 -> 2022 | D15: 278454 | E15: =(D15/D14)-1 -> 0.11473008
B16: =B15+1 -> 12 | C16: =C15+1 -> 2023 | D16: 345967 | E16: =(D16/D15)-1 -> 0.24245656
B17: =B16+1 -> 13 | C17: =C16+1 -> 2024 | D17: =$H$39+B17*$H$40 -> 328507.97 | E17: =(D17/D16)-1 -> -0.050464438
B18: =B17+1 -> 14 | C18: =C17+1 -> 2025 | D18: =$H$39+B18*$H$40 -> 339022.64 | E18: =(D18/D17)-1 -> 0.032007366
B19: =B18+1 -> 15 | C19: =C18+1 -> 2026 | D19: =$H$39+B19*$H$40 -> 349537.32 | E19: =(D19/D18)-1 -> 0.031014668
B20: =B19+1 -> 16 | C20: =C19+1 -> 2027 | D20: =$H$39+B20*$H$40 -> 360051.99 | E20: =(D20/D19)-1 -> 0.030081694
B21: =B20+1 -> 17 | C21: =C20+1 -> 2028 | D21: =$H$39+B21*$H$40 -> 370566.67 | E21: =(D21/D20)-1 -> 0.029203212
B23: Through Forecast Function | G23: SUMMARY OUTPUT
B24: Year | C24: Year | D24: Forecast | E24: Sales Growth
B25: Weight | D25: Function | G25: Regression Statistics
B26: =B17 -> 13 | C26: =C17 -> 2024 | D26: =FORECAST(B17,$D$5:$D$16,$B$5:$B$16) -> 328507.97 | E26: =(D26/D16)-1 -> -0.050464438 | G26: Multiple R | H26: 0.7862606
B27: =B18 -> 14 | C27: =C18 -> 2025 | D27: =FORECAST(B18,$D$5:$D$16,$B$5:$B$16) -> 339022.64 | E27: =(D27/D26)-1 -> 0.032007366 | G27: R Square | H27: 0.61820574
B28: =B19 -> 15 | C28: =C19 -> 2026 | D28: =FORECAST(B19,$D$5:$D$16,$B$5:$B$16) -> 349537.32 | E28: =(D28/D27)-1 -> 0.031014668 | G28: Adjusted R Square | H28: 0.58002631
B29: =B20 -> 16 | C29: =C20 -> 2027 | D29: =FORECAST(B20,$D$5:$D$16,$B$5:$B$16) -> 360051.99 | E29: =(D29/D28)-1 -> 0.030081694 | G29: Standard Error | H29: 31247.268
B30: =B21 -> 17 | C30: =C21 -> 2028 | D30: =FORECAST(B21,$D$5:$D$16,$B$5:$B$16) -> 370566.67 | E30: =(D30/D29)-1 -> 0.029203212 | G30: Observations | H30: 12
G32: ANOVA
H33: df | I33: SS | J33: MS | K33: F | L33: Significance F
G34: Regression | H34: 1 | I34: 1.5809849e+10 | J34: 1.5809849e+10 | K34: 16.192117 | L34: 0.0024230179
G35: Residual | H35: 10 | I35: 9.7639175e+09 | J35: 9.7639175e+08
G36: Total | H36: 11 | I36: 2.5573767e+10
H38: Coefficients | I38: Standard Error | J38: t Stat | K38: P-value | L38: Lower 95% | M38: Upper 95% | N38: Lower 95.0% | O38: Upper 95.0%
G39: Intercept | H39: 191817.2 | I39: 19231.364 | J39: 9.9741858 | K39: 1.6276528e-06 | L39: 148967.05 | M39: 234667.35 | N39: 148967.05 | O39: 234667.35
G40: Year Weight | H40: 10514.675 | I40: 2613.0278 | J40: 4.023943 | K40: 0.0024230179 | L40: 4692.486 | M40: 16336.864 | N40: 4692.486 | O40: 16336.864
